# -*- coding: utf-8 -*-
from odoo import fields, models, api
from odoo.exceptions import ValidationError


class ResCountry(models.Model):
    _inherit = "res.country"
    
    is_active = fields.Boolean('Active')

    @api.model
    def create(self, vals):
        if vals.get('name'):
            vals.update({'name': self.env['res.company']._validate_name(vals.get('name'))})
        return super(ResCountry, self).create(vals)

    @api.multi
    def write(self, vals):
        if vals.get('name'):
            vals.update({'name': self.env['res.company']._validate_name(vals.get('name'))})
        return super(ResCountry, self).write(vals)

    @api.onchange('name')
    def onchange_name(self):
        if self.name:
            name = self.env['res.company']._validate_name(self.name)
            self.name = name

    @api.constrains('name')
    def validate_of_name(self):
        if len(self.sudo().search([('name', '=', self.name)])) > 1:
            raise ValidationError("Country already exists")
